11/09/2025 16:29:29 - INFO - Usuário 'Victor' fez login.
11/09/2025 16:29:36 - INFO - E-mail de recuperação de senha enviado para 'Victor'.
11/09/2025 16:29:40 - INFO - Usuário 'Victor' fez login.
11/09/2025 16:29:51 - INFO - Senha do usuário 'Victor' redefinida com sucesso.
11/09/2025 16:29:53 - INFO - Usuário 'Victor' fez login.
11/09/2025 16:58:33 - INFO - Usuário 'Victor' fez logout.
11/09/2025 16:58:35 - INFO - Usuário 'Aluno' fez login.
11/09/2025 17:00:55 - INFO - Usuário 'Aluno' fez logout.
11/09/2025 17:00:58 - INFO - Usuário 'Aluno' fez login.
11/09/2025 17:01:40 - INFO - Usuário 'Aluno' concluiu a prova 'Aula 01' com pontuação 1/1.
11/09/2025 18:41:03 - INFO - Usuário 'Aluno' concluiu a prova 'Aula 01' com pontuação 1/1.
11/09/2025 19:05:21 - INFO - Usuário 'Aluno' fez logout.
11/09/2025 19:05:24 - INFO - Usuário 'Aluno' fez login.
11/09/2025 19:05:26 - INFO - Usuário 'Aluno' fez logout.
11/09/2025 19:05:32 - INFO - E-mail de recuperação de senha enviado para 'Victor'.
11/09/2025 19:05:46 - INFO - Usuário 'Victor' fez login.
11/09/2025 19:05:49 - INFO - Usuário 'Victor' fez logout.
11/09/2025 19:05:54 - INFO - Usuário 'Professor' fez login.
11/09/2025 19:06:05 - INFO - Usuário 'Professor' fez logout.
11/09/2025 19:06:07 - INFO - Usuário 'Aluno' fez login.
11/09/2025 19:06:14 - INFO - Usuário 'Aluno' concluiu a prova 'Aula 01' com pontuação 1/1.
11/09/2025 20:21:37 - INFO - Usuário 'Aluno' concluiu a prova 'Aula 01' com pontuação 1/1.
11/09/2025 20:38:04 - INFO - Usuário 'Aluno' fez logout.
11/09/2025 20:38:06 - INFO - Usuário 'Professor' fez login.
11/09/2025 20:38:11 - INFO - Usuário 'Professor' fez logout.
11/09/2025 20:38:13 - INFO - Usuário 'Victor' fez login.
11/09/2025 20:41:12 - INFO - Usuário 'Victor' fez logout.
11/09/2025 20:41:14 - INFO - Usuário 'Professor' fez login.
11/09/2025 20:41:17 - INFO - Usuário 'Professor' fez logout.
11/09/2025 20:41:19 - INFO - Usuário 'Aluno' fez login.
11/09/2025 20:49:36 - INFO - Usuário 'Aluno' fez logout.
11/09/2025 20:49:38 - INFO - Usuário 'Professor' fez login.
11/09/2025 20:52:25 - INFO - Usuário 'Professor' fez logout.
11/09/2025 20:52:27 - INFO - Usuário 'Aluno' fez login.
11/09/2025 20:52:32 - INFO - Usuário 'Aluno' concluiu a prova 'Aula 01' com pontuação 1/1.
11/09/2025 20:52:34 - INFO - Usuário 'Aluno' fez logout.
11/09/2025 20:52:36 - INFO - Usuário 'Professor' fez login.
11/09/2025 21:33:25 - INFO - Usuário 'Professor' fez logout.
11/09/2025 21:33:27 - INFO - Usuário 'Aluno' fez login.
11/09/2025 23:44:10 - INFO - Usuário 'Aluno' fez logout.
11/09/2025 23:44:15 - INFO - Usuário 'Victor' fez login.
11/09/2025 23:44:31 - INFO - Usuário 'Victor' fez logout.
11/09/2025 23:44:33 - INFO - Usuário 'Professor' fez login.
11/09/2025 23:49:48 - INFO - Usuário 'Professor' fez logout.
11/09/2025 23:49:49 - INFO - Usuário 'Aluno' fez login.
11/09/2025 23:53:11 - INFO - Usuário 'Aluno' fez logout.
11/09/2025 23:53:14 - INFO - Usuário 'Professor' fez login.
11/09/2025 23:53:18 - INFO - Usuário 'Professor' fez logout.
11/09/2025 23:53:21 - INFO - Usuário 'Victor' fez login.
11/09/2025 23:56:03 - INFO - Usuário 'Victor' fez logout.
11/09/2025 23:56:07 - INFO - Usuário 'Aluno' fez login.
12/09/2025 10:01:04 - INFO - Usuário 'Aluno' fez logout.
12/09/2025 10:01:06 - INFO - Usuário 'Professor' fez login.
12/09/2025 10:01:43 - INFO - Usuário 'Professor' fez logout.
12/09/2025 10:01:46 - INFO - Usuário 'Victor' fez login.
12/09/2025 10:01:47 - INFO - Usuário 'Victor' fez logout.
12/09/2025 10:01:49 - INFO - Usuário 'Aluno' fez login.
12/09/2025 10:04:02 - INFO - Usuário 'Aluno' fez logout.
12/09/2025 10:04:04 - INFO - Usuário 'Professor' fez login.
12/09/2025 10:04:10 - INFO - Usuário 'Victor' fez login.
12/09/2025 10:04:14 - INFO - Usuário 'Victor' fez logout.
12/09/2025 10:04:17 - INFO - Usuário 'Aluno' fez login.
12/09/2025 11:34:28 - INFO - Usuário 'Aluno' fez logout.
12/09/2025 11:34:30 - INFO - Usuário 'Professor' fez login.
12/09/2025 11:34:41 - INFO - Usuário 'Professor' fez logout.
12/09/2025 11:34:43 - INFO - Usuário 'Aluno' fez login.
12/09/2025 11:39:53 - INFO - Usuário 'Aluno' fez logout.
12/09/2025 11:39:55 - INFO - Usuário 'Professor' fez login.
12/09/2025 11:40:24 - INFO - Usuário 'Professor' fez logout.
12/09/2025 11:40:26 - INFO - Usuário 'Victor' fez login.
12/09/2025 15:08:18 - INFO - Usuário 'Victor' EXPORTOU os dados para PDF.
12/09/2025 15:10:39 - INFO - Usuário 'Victor' fez logout.
12/09/2025 15:10:42 - INFO - Usuário 'Aluno' fez login.
12/09/2025 15:10:54 - INFO - Usuário 'Aluno' fez logout.
12/09/2025 15:10:56 - INFO - Usuário 'Professor' fez login.
12/09/2025 15:12:57 - INFO - Usuário 'Professor' fez logout.
12/09/2025 15:13:00 - INFO - Usuário 'Aluno' fez login.
12/09/2025 18:17:52 - INFO - Usuário 'Aluno' concluiu a prova 'Aula 01' com pontuação 1/1.
12/09/2025 19:04:20 - INFO - Usuário 'Aluno' fez logout.
12/09/2025 19:04:22 - INFO - Usuário 'Professor' fez login.
12/09/2025 19:04:24 - INFO - Usuário 'Professor' fez logout.
12/09/2025 19:04:27 - INFO - Usuário 'Victor' fez login.
12/09/2025 19:04:28 - INFO - Usuário 'Victor' fez logout.
12/09/2025 19:04:30 - INFO - Usuário 'Aluno' fez login.
12/09/2025 19:04:33 - INFO - Usuário 'Aluno' fez logout.
12/09/2025 19:04:35 - INFO - Usuário 'Professor' fez login.
12/09/2025 19:29:50 - INFO - Usuário 'Professor' fez logout.
12/09/2025 19:31:33 - INFO - Usuário 'Professor' fez login.
12/09/2025 19:31:39 - INFO - Usuário 'Aluno' fez login.
12/09/2025 19:31:44 - INFO - Usuário 'Victor' fez login.
12/09/2025 20:29:12 - INFO - Usuário 'Victor' fez logout.
12/09/2025 20:29:15 - INFO - Usuário 'Aluno' fez login.
12/09/2025 20:49:02 - INFO - Usuário 'Victor' fez logout.
12/09/2025 20:49:07 - ERROR - Exception on /esqueci_a_senha [POST]
Traceback (most recent call last):
  File "C:\Users\Corsini\AppData\Local\Programs\Python\Python313\Lib\site-packages\flask\app.py", line 1511, in wsgi_app
    response = self.full_dispatch_request()
  File "C:\Users\Corsini\AppData\Local\Programs\Python\Python313\Lib\site-packages\flask\app.py", line 919, in full_dispatch_request
    rv = self.handle_user_exception(e)
  File "C:\Users\Corsini\AppData\Local\Programs\Python\Python313\Lib\site-packages\flask\app.py", line 917, in full_dispatch_request
    rv = self.dispatch_request()
  File "C:\Users\Corsini\AppData\Local\Programs\Python\Python313\Lib\site-packages\flask\app.py", line 902, in dispatch_request
    return self.ensure_sync(self.view_functions[rule.endpoint])(**view_args)  # type: ignore[no-any-return]
           ~~~~~~~~~~~~~~~~~~~~~~~~~~~~~~~~~~~~~~~~~~~~~~~~~~~~^^^^^^^^^^^^^
  File "C:\Users\Corsini\Desktop\teste\app.py", line 132, in esqueci_a_senha
    link_redefinicao = url_for('redefinir_senha', token=token, _external=True)
  File "C:\Users\Corsini\AppData\Local\Programs\Python\Python313\Lib\site-packages\flask\helpers.py", line 239, in url_for
    return current_app.url_for(
           ~~~~~~~~~~~~~~~~~~~^
        endpoint,
        ^^^^^^^^^
    ...<4 lines>...
        **values,
        ^^^^^^^^^
    )
    ^
  File "C:\Users\Corsini\AppData\Local\Programs\Python\Python313\Lib\site-packages\flask\app.py", line 1121, in url_for
    return self.handle_url_build_error(error, endpoint, values)
           ~~~~~~~~~~~~~~~~~~~~~~~~~~~^^^^^^^^^^^^^^^^^^^^^^^^^
  File "C:\Users\Corsini\AppData\Local\Programs\Python\Python313\Lib\site-packages\flask\app.py", line 1110, in url_for
    rv = url_adapter.build(  # type: ignore[union-attr]
        endpoint,
    ...<3 lines>...
        force_external=_external,
    )
  File "C:\Users\Corsini\AppData\Local\Programs\Python\Python313\Lib\site-packages\werkzeug\routing\map.py", line 924, in build
    raise BuildError(endpoint, values, method, self)
werkzeug.routing.exceptions.BuildError: Could not build url for endpoint 'redefinir_senha' with values ['token']. Did you mean 'esqueci_a_senha' instead?
12/09/2025 20:53:13 - ERROR - Exception on /esqueci_a_senha [POST]
Traceback (most recent call last):
  File "C:\Users\Corsini\AppData\Local\Programs\Python\Python313\Lib\site-packages\flask\app.py", line 1511, in wsgi_app
    response = self.full_dispatch_request()
  File "C:\Users\Corsini\AppData\Local\Programs\Python\Python313\Lib\site-packages\flask\app.py", line 919, in full_dispatch_request
    rv = self.handle_user_exception(e)
  File "C:\Users\Corsini\AppData\Local\Programs\Python\Python313\Lib\site-packages\flask\app.py", line 917, in full_dispatch_request
    rv = self.dispatch_request()
  File "C:\Users\Corsini\AppData\Local\Programs\Python\Python313\Lib\site-packages\flask\app.py", line 902, in dispatch_request
    return self.ensure_sync(self.view_functions[rule.endpoint])(**view_args)  # type: ignore[no-any-return]
           ~~~~~~~~~~~~~~~~~~~~~~~~~~~~~~~~~~~~~~~~~~~~~~~~~~~~^^^^^^^^^^^^^
  File "C:\Users\Corsini\Desktop\teste\app.py", line 132, in esqueci_a_senha
    link_redefinicao = url_for('redefinir_senha', token=token, _external=True)
  File "C:\Users\Corsini\AppData\Local\Programs\Python\Python313\Lib\site-packages\flask\helpers.py", line 239, in url_for
    return current_app.url_for(
           ~~~~~~~~~~~~~~~~~~~^
        endpoint,
        ^^^^^^^^^
    ...<4 lines>...
        **values,
        ^^^^^^^^^
    )
    ^
  File "C:\Users\Corsini\AppData\Local\Programs\Python\Python313\Lib\site-packages\flask\app.py", line 1121, in url_for
    return self.handle_url_build_error(error, endpoint, values)
           ~~~~~~~~~~~~~~~~~~~~~~~~~~~^^^^^^^^^^^^^^^^^^^^^^^^^
  File "C:\Users\Corsini\AppData\Local\Programs\Python\Python313\Lib\site-packages\flask\app.py", line 1110, in url_for
    rv = url_adapter.build(  # type: ignore[union-attr]
        endpoint,
    ...<3 lines>...
        force_external=_external,
    )
  File "C:\Users\Corsini\AppData\Local\Programs\Python\Python313\Lib\site-packages\werkzeug\routing\map.py", line 924, in build
    raise BuildError(endpoint, values, method, self)
werkzeug.routing.exceptions.BuildError: Could not build url for endpoint 'redefinir_senha' with values ['token']. Did you mean 'esqueci_a_senha' instead?
12/09/2025 20:55:23 - ERROR - Exception on /esqueci_a_senha [POST]
Traceback (most recent call last):
  File "C:\Users\Corsini\AppData\Local\Programs\Python\Python313\Lib\site-packages\flask\app.py", line 1511, in wsgi_app
    response = self.full_dispatch_request()
  File "C:\Users\Corsini\AppData\Local\Programs\Python\Python313\Lib\site-packages\flask\app.py", line 919, in full_dispatch_request
    rv = self.handle_user_exception(e)
  File "C:\Users\Corsini\AppData\Local\Programs\Python\Python313\Lib\site-packages\flask\app.py", line 917, in full_dispatch_request
    rv = self.dispatch_request()
  File "C:\Users\Corsini\AppData\Local\Programs\Python\Python313\Lib\site-packages\flask\app.py", line 902, in dispatch_request
    return self.ensure_sync(self.view_functions[rule.endpoint])(**view_args)  # type: ignore[no-any-return]
           ~~~~~~~~~~~~~~~~~~~~~~~~~~~~~~~~~~~~~~~~~~~~~~~~~~~~^^^^^^^^^^^^^
  File "C:\Users\Corsini\Desktop\teste\app.py", line 132, in esqueci_a_senha
    link_redefinicao = url_for('redefinir_senha', token=token, _external=True)
  File "C:\Users\Corsini\AppData\Local\Programs\Python\Python313\Lib\site-packages\flask\helpers.py", line 239, in url_for
    return current_app.url_for(
           ~~~~~~~~~~~~~~~~~~~^
        endpoint,
        ^^^^^^^^^
    ...<4 lines>...
        **values,
        ^^^^^^^^^
    )
    ^
  File "C:\Users\Corsini\AppData\Local\Programs\Python\Python313\Lib\site-packages\flask\app.py", line 1121, in url_for
    return self.handle_url_build_error(error, endpoint, values)
           ~~~~~~~~~~~~~~~~~~~~~~~~~~~^^^^^^^^^^^^^^^^^^^^^^^^^
  File "C:\Users\Corsini\AppData\Local\Programs\Python\Python313\Lib\site-packages\flask\app.py", line 1110, in url_for
    rv = url_adapter.build(  # type: ignore[union-attr]
        endpoint,
    ...<3 lines>...
        force_external=_external,
    )
  File "C:\Users\Corsini\AppData\Local\Programs\Python\Python313\Lib\site-packages\werkzeug\routing\map.py", line 924, in build
    raise BuildError(endpoint, values, method, self)
werkzeug.routing.exceptions.BuildError: Could not build url for endpoint 'redefinir_senha' with values ['token']. Did you mean 'esqueci_a_senha' instead?
12/09/2025 20:55:25 - ERROR - Exception on /esqueci_a_senha [POST]
Traceback (most recent call last):
  File "C:\Users\Corsini\AppData\Local\Programs\Python\Python313\Lib\site-packages\flask\app.py", line 1511, in wsgi_app
    response = self.full_dispatch_request()
  File "C:\Users\Corsini\AppData\Local\Programs\Python\Python313\Lib\site-packages\flask\app.py", line 919, in full_dispatch_request
    rv = self.handle_user_exception(e)
  File "C:\Users\Corsini\AppData\Local\Programs\Python\Python313\Lib\site-packages\flask\app.py", line 917, in full_dispatch_request
    rv = self.dispatch_request()
  File "C:\Users\Corsini\AppData\Local\Programs\Python\Python313\Lib\site-packages\flask\app.py", line 902, in dispatch_request
    return self.ensure_sync(self.view_functions[rule.endpoint])(**view_args)  # type: ignore[no-any-return]
           ~~~~~~~~~~~~~~~~~~~~~~~~~~~~~~~~~~~~~~~~~~~~~~~~~~~~^^^^^^^^^^^^^
  File "C:\Users\Corsini\Desktop\teste\app.py", line 132, in esqueci_a_senha
    link_redefinicao = url_for('redefinir_senha', token=token, _external=True)
  File "C:\Users\Corsini\AppData\Local\Programs\Python\Python313\Lib\site-packages\flask\helpers.py", line 239, in url_for
    return current_app.url_for(
           ~~~~~~~~~~~~~~~~~~~^
        endpoint,
        ^^^^^^^^^
    ...<4 lines>...
        **values,
        ^^^^^^^^^
    )
    ^
  File "C:\Users\Corsini\AppData\Local\Programs\Python\Python313\Lib\site-packages\flask\app.py", line 1121, in url_for
    return self.handle_url_build_error(error, endpoint, values)
           ~~~~~~~~~~~~~~~~~~~~~~~~~~~^^^^^^^^^^^^^^^^^^^^^^^^^
  File "C:\Users\Corsini\AppData\Local\Programs\Python\Python313\Lib\site-packages\flask\app.py", line 1110, in url_for
    rv = url_adapter.build(  # type: ignore[union-attr]
        endpoint,
    ...<3 lines>...
        force_external=_external,
    )
  File "C:\Users\Corsini\AppData\Local\Programs\Python\Python313\Lib\site-packages\werkzeug\routing\map.py", line 924, in build
    raise BuildError(endpoint, values, method, self)
werkzeug.routing.exceptions.BuildError: Could not build url for endpoint 'redefinir_senha' with values ['token']. Did you mean 'esqueci_a_senha' instead?
12/09/2025 20:55:25 - ERROR - Exception on /esqueci_a_senha [POST]
Traceback (most recent call last):
  File "C:\Users\Corsini\AppData\Local\Programs\Python\Python313\Lib\site-packages\flask\app.py", line 1511, in wsgi_app
    response = self.full_dispatch_request()
  File "C:\Users\Corsini\AppData\Local\Programs\Python\Python313\Lib\site-packages\flask\app.py", line 919, in full_dispatch_request
    rv = self.handle_user_exception(e)
  File "C:\Users\Corsini\AppData\Local\Programs\Python\Python313\Lib\site-packages\flask\app.py", line 917, in full_dispatch_request
    rv = self.dispatch_request()
  File "C:\Users\Corsini\AppData\Local\Programs\Python\Python313\Lib\site-packages\flask\app.py", line 902, in dispatch_request
    return self.ensure_sync(self.view_functions[rule.endpoint])(**view_args)  # type: ignore[no-any-return]
           ~~~~~~~~~~~~~~~~~~~~~~~~~~~~~~~~~~~~~~~~~~~~~~~~~~~~^^^^^^^^^^^^^
  File "C:\Users\Corsini\Desktop\teste\app.py", line 132, in esqueci_a_senha
    link_redefinicao = url_for('redefinir_senha', token=token, _external=True)
  File "C:\Users\Corsini\AppData\Local\Programs\Python\Python313\Lib\site-packages\flask\helpers.py", line 239, in url_for
    return current_app.url_for(
           ~~~~~~~~~~~~~~~~~~~^
        endpoint,
        ^^^^^^^^^
    ...<4 lines>...
        **values,
        ^^^^^^^^^
    )
    ^
  File "C:\Users\Corsini\AppData\Local\Programs\Python\Python313\Lib\site-packages\flask\app.py", line 1121, in url_for
    return self.handle_url_build_error(error, endpoint, values)
           ~~~~~~~~~~~~~~~~~~~~~~~~~~~^^^^^^^^^^^^^^^^^^^^^^^^^
  File "C:\Users\Corsini\AppData\Local\Programs\Python\Python313\Lib\site-packages\flask\app.py", line 1110, in url_for
    rv = url_adapter.build(  # type: ignore[union-attr]
        endpoint,
    ...<3 lines>...
        force_external=_external,
    )
  File "C:\Users\Corsini\AppData\Local\Programs\Python\Python313\Lib\site-packages\werkzeug\routing\map.py", line 924, in build
    raise BuildError(endpoint, values, method, self)
werkzeug.routing.exceptions.BuildError: Could not build url for endpoint 'redefinir_senha' with values ['token']. Did you mean 'esqueci_a_senha' instead?
12/09/2025 20:55:27 - ERROR - Exception on /esqueci_a_senha [POST]
Traceback (most recent call last):
  File "C:\Users\Corsini\AppData\Local\Programs\Python\Python313\Lib\site-packages\flask\app.py", line 1511, in wsgi_app
    response = self.full_dispatch_request()
  File "C:\Users\Corsini\AppData\Local\Programs\Python\Python313\Lib\site-packages\flask\app.py", line 919, in full_dispatch_request
    rv = self.handle_user_exception(e)
  File "C:\Users\Corsini\AppData\Local\Programs\Python\Python313\Lib\site-packages\flask\app.py", line 917, in full_dispatch_request
    rv = self.dispatch_request()
  File "C:\Users\Corsini\AppData\Local\Programs\Python\Python313\Lib\site-packages\flask\app.py", line 902, in dispatch_request
    return self.ensure_sync(self.view_functions[rule.endpoint])(**view_args)  # type: ignore[no-any-return]
           ~~~~~~~~~~~~~~~~~~~~~~~~~~~~~~~~~~~~~~~~~~~~~~~~~~~~^^^^^^^^^^^^^
  File "C:\Users\Corsini\Desktop\teste\app.py", line 132, in esqueci_a_senha
    link_redefinicao = url_for('redefinir_senha', token=token, _external=True)
  File "C:\Users\Corsini\AppData\Local\Programs\Python\Python313\Lib\site-packages\flask\helpers.py", line 239, in url_for
    return current_app.url_for(
           ~~~~~~~~~~~~~~~~~~~^
        endpoint,
        ^^^^^^^^^
    ...<4 lines>...
        **values,
        ^^^^^^^^^
    )
    ^
  File "C:\Users\Corsini\AppData\Local\Programs\Python\Python313\Lib\site-packages\flask\app.py", line 1121, in url_for
    return self.handle_url_build_error(error, endpoint, values)
           ~~~~~~~~~~~~~~~~~~~~~~~~~~~^^^^^^^^^^^^^^^^^^^^^^^^^
  File "C:\Users\Corsini\AppData\Local\Programs\Python\Python313\Lib\site-packages\flask\app.py", line 1110, in url_for
    rv = url_adapter.build(  # type: ignore[union-attr]
        endpoint,
    ...<3 lines>...
        force_external=_external,
    )
  File "C:\Users\Corsini\AppData\Local\Programs\Python\Python313\Lib\site-packages\werkzeug\routing\map.py", line 924, in build
    raise BuildError(endpoint, values, method, self)
werkzeug.routing.exceptions.BuildError: Could not build url for endpoint 'redefinir_senha' with values ['token']. Did you mean 'esqueci_a_senha' instead?
12/09/2025 20:57:46 - ERROR - Exception on /esqueci_a_senha [POST]
Traceback (most recent call last):
  File "C:\Users\Corsini\AppData\Local\Programs\Python\Python313\Lib\site-packages\flask\app.py", line 1511, in wsgi_app
    response = self.full_dispatch_request()
  File "C:\Users\Corsini\AppData\Local\Programs\Python\Python313\Lib\site-packages\flask\app.py", line 919, in full_dispatch_request
    rv = self.handle_user_exception(e)
  File "C:\Users\Corsini\AppData\Local\Programs\Python\Python313\Lib\site-packages\flask\app.py", line 917, in full_dispatch_request
    rv = self.dispatch_request()
  File "C:\Users\Corsini\AppData\Local\Programs\Python\Python313\Lib\site-packages\flask\app.py", line 902, in dispatch_request
    return self.ensure_sync(self.view_functions[rule.endpoint])(**view_args)  # type: ignore[no-any-return]
           ~~~~~~~~~~~~~~~~~~~~~~~~~~~~~~~~~~~~~~~~~~~~~~~~~~~~^^^^^^^^^^^^^
  File "C:\Users\Corsini\Desktop\teste\app.py", line 132, in esqueci_a_senha
    link_redefinicao = url_for('redefinir_senha', token=token, _external=True)
  File "C:\Users\Corsini\AppData\Local\Programs\Python\Python313\Lib\site-packages\flask\helpers.py", line 239, in url_for
    return current_app.url_for(
           ~~~~~~~~~~~~~~~~~~~^
        endpoint,
        ^^^^^^^^^
    ...<4 lines>...
        **values,
        ^^^^^^^^^
    )
    ^
  File "C:\Users\Corsini\AppData\Local\Programs\Python\Python313\Lib\site-packages\flask\app.py", line 1121, in url_for
    return self.handle_url_build_error(error, endpoint, values)
           ~~~~~~~~~~~~~~~~~~~~~~~~~~~^^^^^^^^^^^^^^^^^^^^^^^^^
  File "C:\Users\Corsini\AppData\Local\Programs\Python\Python313\Lib\site-packages\flask\app.py", line 1110, in url_for
    rv = url_adapter.build(  # type: ignore[union-attr]
        endpoint,
    ...<3 lines>...
        force_external=_external,
    )
  File "C:\Users\Corsini\AppData\Local\Programs\Python\Python313\Lib\site-packages\werkzeug\routing\map.py", line 924, in build
    raise BuildError(endpoint, values, method, self)
werkzeug.routing.exceptions.BuildError: Could not build url for endpoint 'redefinir_senha' with values ['token']. Did you mean 'esqueci_a_senha' instead?
12/09/2025 20:57:47 - ERROR - Exception on /esqueci_a_senha [POST]
Traceback (most recent call last):
  File "C:\Users\Corsini\AppData\Local\Programs\Python\Python313\Lib\site-packages\flask\app.py", line 1511, in wsgi_app
    response = self.full_dispatch_request()
  File "C:\Users\Corsini\AppData\Local\Programs\Python\Python313\Lib\site-packages\flask\app.py", line 919, in full_dispatch_request
    rv = self.handle_user_exception(e)
  File "C:\Users\Corsini\AppData\Local\Programs\Python\Python313\Lib\site-packages\flask\app.py", line 917, in full_dispatch_request
    rv = self.dispatch_request()
  File "C:\Users\Corsini\AppData\Local\Programs\Python\Python313\Lib\site-packages\flask\app.py", line 902, in dispatch_request
    return self.ensure_sync(self.view_functions[rule.endpoint])(**view_args)  # type: ignore[no-any-return]
           ~~~~~~~~~~~~~~~~~~~~~~~~~~~~~~~~~~~~~~~~~~~~~~~~~~~~^^^^^^^^^^^^^
  File "C:\Users\Corsini\Desktop\teste\app.py", line 132, in esqueci_a_senha
    link_redefinicao = url_for('redefinir_senha', token=token, _external=True)
  File "C:\Users\Corsini\AppData\Local\Programs\Python\Python313\Lib\site-packages\flask\helpers.py", line 239, in url_for
    return current_app.url_for(
           ~~~~~~~~~~~~~~~~~~~^
        endpoint,
        ^^^^^^^^^
    ...<4 lines>...
        **values,
        ^^^^^^^^^
    )
    ^
  File "C:\Users\Corsini\AppData\Local\Programs\Python\Python313\Lib\site-packages\flask\app.py", line 1121, in url_for
    return self.handle_url_build_error(error, endpoint, values)
           ~~~~~~~~~~~~~~~~~~~~~~~~~~~^^^^^^^^^^^^^^^^^^^^^^^^^
  File "C:\Users\Corsini\AppData\Local\Programs\Python\Python313\Lib\site-packages\flask\app.py", line 1110, in url_for
    rv = url_adapter.build(  # type: ignore[union-attr]
        endpoint,
    ...<3 lines>...
        force_external=_external,
    )
  File "C:\Users\Corsini\AppData\Local\Programs\Python\Python313\Lib\site-packages\werkzeug\routing\map.py", line 924, in build
    raise BuildError(endpoint, values, method, self)
werkzeug.routing.exceptions.BuildError: Could not build url for endpoint 'redefinir_senha' with values ['token']. Did you mean 'esqueci_a_senha' instead?
12/09/2025 20:57:48 - ERROR - Exception on /esqueci_a_senha [POST]
Traceback (most recent call last):
  File "C:\Users\Corsini\AppData\Local\Programs\Python\Python313\Lib\site-packages\flask\app.py", line 1511, in wsgi_app
    response = self.full_dispatch_request()
  File "C:\Users\Corsini\AppData\Local\Programs\Python\Python313\Lib\site-packages\flask\app.py", line 919, in full_dispatch_request
    rv = self.handle_user_exception(e)
  File "C:\Users\Corsini\AppData\Local\Programs\Python\Python313\Lib\site-packages\flask\app.py", line 917, in full_dispatch_request
    rv = self.dispatch_request()
  File "C:\Users\Corsini\AppData\Local\Programs\Python\Python313\Lib\site-packages\flask\app.py", line 902, in dispatch_request
    return self.ensure_sync(self.view_functions[rule.endpoint])(**view_args)  # type: ignore[no-any-return]
           ~~~~~~~~~~~~~~~~~~~~~~~~~~~~~~~~~~~~~~~~~~~~~~~~~~~~^^^^^^^^^^^^^
  File "C:\Users\Corsini\Desktop\teste\app.py", line 132, in esqueci_a_senha
    link_redefinicao = url_for('redefinir_senha', token=token, _external=True)
  File "C:\Users\Corsini\AppData\Local\Programs\Python\Python313\Lib\site-packages\flask\helpers.py", line 239, in url_for
    return current_app.url_for(
           ~~~~~~~~~~~~~~~~~~~^
        endpoint,
        ^^^^^^^^^
    ...<4 lines>...
        **values,
        ^^^^^^^^^
    )
    ^
  File "C:\Users\Corsini\AppData\Local\Programs\Python\Python313\Lib\site-packages\flask\app.py", line 1121, in url_for
    return self.handle_url_build_error(error, endpoint, values)
           ~~~~~~~~~~~~~~~~~~~~~~~~~~~^^^^^^^^^^^^^^^^^^^^^^^^^
  File "C:\Users\Corsini\AppData\Local\Programs\Python\Python313\Lib\site-packages\flask\app.py", line 1110, in url_for
    rv = url_adapter.build(  # type: ignore[union-attr]
        endpoint,
    ...<3 lines>...
        force_external=_external,
    )
  File "C:\Users\Corsini\AppData\Local\Programs\Python\Python313\Lib\site-packages\werkzeug\routing\map.py", line 924, in build
    raise BuildError(endpoint, values, method, self)
werkzeug.routing.exceptions.BuildError: Could not build url for endpoint 'redefinir_senha' with values ['token']. Did you mean 'esqueci_a_senha' instead?
12/09/2025 20:57:49 - ERROR - Exception on /esqueci_a_senha [POST]
Traceback (most recent call last):
  File "C:\Users\Corsini\AppData\Local\Programs\Python\Python313\Lib\site-packages\flask\app.py", line 1511, in wsgi_app
    response = self.full_dispatch_request()
  File "C:\Users\Corsini\AppData\Local\Programs\Python\Python313\Lib\site-packages\flask\app.py", line 919, in full_dispatch_request
    rv = self.handle_user_exception(e)
  File "C:\Users\Corsini\AppData\Local\Programs\Python\Python313\Lib\site-packages\flask\app.py", line 917, in full_dispatch_request
    rv = self.dispatch_request()
  File "C:\Users\Corsini\AppData\Local\Programs\Python\Python313\Lib\site-packages\flask\app.py", line 902, in dispatch_request
    return self.ensure_sync(self.view_functions[rule.endpoint])(**view_args)  # type: ignore[no-any-return]
           ~~~~~~~~~~~~~~~~~~~~~~~~~~~~~~~~~~~~~~~~~~~~~~~~~~~~^^^^^^^^^^^^^
  File "C:\Users\Corsini\Desktop\teste\app.py", line 132, in esqueci_a_senha
    link_redefinicao = url_for('redefinir_senha', token=token, _external=True)
  File "C:\Users\Corsini\AppData\Local\Programs\Python\Python313\Lib\site-packages\flask\helpers.py", line 239, in url_for
    return current_app.url_for(
           ~~~~~~~~~~~~~~~~~~~^
        endpoint,
        ^^^^^^^^^
    ...<4 lines>...
        **values,
        ^^^^^^^^^
    )
    ^
  File "C:\Users\Corsini\AppData\Local\Programs\Python\Python313\Lib\site-packages\flask\app.py", line 1121, in url_for
    return self.handle_url_build_error(error, endpoint, values)
           ~~~~~~~~~~~~~~~~~~~~~~~~~~~^^^^^^^^^^^^^^^^^^^^^^^^^
  File "C:\Users\Corsini\AppData\Local\Programs\Python\Python313\Lib\site-packages\flask\app.py", line 1110, in url_for
    rv = url_adapter.build(  # type: ignore[union-attr]
        endpoint,
    ...<3 lines>...
        force_external=_external,
    )
  File "C:\Users\Corsini\AppData\Local\Programs\Python\Python313\Lib\site-packages\werkzeug\routing\map.py", line 924, in build
    raise BuildError(endpoint, values, method, self)
werkzeug.routing.exceptions.BuildError: Could not build url for endpoint 'redefinir_senha' with values ['token']. Did you mean 'esqueci_a_senha' instead?
12/09/2025 20:58:19 - INFO - Usuário 'Victor' fez login.
12/09/2025 20:58:26 - ERROR - Exception on /esqueci_a_senha [POST]
Traceback (most recent call last):
  File "C:\Users\Corsini\AppData\Local\Programs\Python\Python313\Lib\site-packages\flask\app.py", line 1511, in wsgi_app
    response = self.full_dispatch_request()
  File "C:\Users\Corsini\AppData\Local\Programs\Python\Python313\Lib\site-packages\flask\app.py", line 919, in full_dispatch_request
    rv = self.handle_user_exception(e)
  File "C:\Users\Corsini\AppData\Local\Programs\Python\Python313\Lib\site-packages\flask\app.py", line 917, in full_dispatch_request
    rv = self.dispatch_request()
  File "C:\Users\Corsini\AppData\Local\Programs\Python\Python313\Lib\site-packages\flask\app.py", line 902, in dispatch_request
    return self.ensure_sync(self.view_functions[rule.endpoint])(**view_args)  # type: ignore[no-any-return]
           ~~~~~~~~~~~~~~~~~~~~~~~~~~~~~~~~~~~~~~~~~~~~~~~~~~~~^^^^^^^^^^^^^
  File "C:\Users\Corsini\Desktop\teste\app.py", line 132, in esqueci_a_senha
    link_redefinicao = url_for('redefinir_senha', token=token, _external=True)
  File "C:\Users\Corsini\AppData\Local\Programs\Python\Python313\Lib\site-packages\flask\helpers.py", line 239, in url_for
    return current_app.url_for(
           ~~~~~~~~~~~~~~~~~~~^
        endpoint,
        ^^^^^^^^^
    ...<4 lines>...
        **values,
        ^^^^^^^^^
    )
    ^
  File "C:\Users\Corsini\AppData\Local\Programs\Python\Python313\Lib\site-packages\flask\app.py", line 1121, in url_for
    return self.handle_url_build_error(error, endpoint, values)
           ~~~~~~~~~~~~~~~~~~~~~~~~~~~^^^^^^^^^^^^^^^^^^^^^^^^^
  File "C:\Users\Corsini\AppData\Local\Programs\Python\Python313\Lib\site-packages\flask\app.py", line 1110, in url_for
    rv = url_adapter.build(  # type: ignore[union-attr]
        endpoint,
    ...<3 lines>...
        force_external=_external,
    )
  File "C:\Users\Corsini\AppData\Local\Programs\Python\Python313\Lib\site-packages\werkzeug\routing\map.py", line 924, in build
    raise BuildError(endpoint, values, method, self)
werkzeug.routing.exceptions.BuildError: Could not build url for endpoint 'redefinir_senha' with values ['token']. Did you mean 'esqueci_a_senha' instead?
12/09/2025 20:59:41 - INFO - E-mail de recuperação de senha enviado para 'Victor'.
12/09/2025 20:59:56 - INFO - Senha do usuário 'Victor' redefinida com sucesso.
12/09/2025 21:00:12 - INFO - Usuário 'Victor' fez login.
